[2022-12-05T00:23:15] ERROR [django.request.log_response:241] Internal Server Error: /apps/editapp/instagram
Traceback (most recent call last):
  File "D:\yash\billsnap\env\lib\site-packages\django\db\backends\utils.py", line 89, in _execute
    return self.cursor.execute(sql, params)
  File "D:\yash\billsnap\env\lib\site-packages\django\db\backends\sqlite3\base.py", line 357, in execute
    return Database.Cursor.execute(self, query, params)
sqlite3.IntegrityError: UNIQUE constraint failed: apps_applists.slug

The above exception was the direct cause of the following exception:

Traceback (most recent call last):
  File "D:\yash\billsnap\env\lib\site-packages\django\core\handlers\exception.py", line 55, in inner
    response = get_response(request)
  File "D:\yash\billsnap\env\lib\site-packages\django\core\handlers\base.py", line 197, in _get_response
    response = wrapped_callback(request, *callback_args, **callback_kwargs)
  File "D:\yash\billsnap\env\lib\site-packages\django\contrib\auth\decorators.py", line 23, in _wrapped_view
    return view_func(request, *args, **kwargs)
  File "D:\yash\billsnap\billsnapdec\apps\views.py", line 95, in editapp
    app.save()
  File "D:\yash\billsnap\billsnapdec\apps\models.py", line 33, in save
    super(applists, self).save()
  File "D:\yash\billsnap\env\lib\site-packages\django\db\models\base.py", line 812, in save
    self.save_base(
  File "D:\yash\billsnap\env\lib\site-packages\django\db\models\base.py", line 863, in save_base
    updated = self._save_table(
  File "D:\yash\billsnap\env\lib\site-packages\django\db\models\base.py", line 1006, in _save_table
    results = self._do_insert(
  File "D:\yash\billsnap\env\lib\site-packages\django\db\models\base.py", line 1047, in _do_insert
    return manager._insert(
  File "D:\yash\billsnap\env\lib\site-packages\django\db\models\manager.py", line 85, in manager_method
    return getattr(self.get_queryset(), name)(*args, **kwargs)
  File "D:\yash\billsnap\env\lib\site-packages\django\db\models\query.py", line 1790, in _insert
    return query.get_compiler(using=using).execute_sql(returning_fields)
  File "D:\yash\billsnap\env\lib\site-packages\django\db\models\sql\compiler.py", line 1660, in execute_sql
    cursor.execute(sql, params)
  File "D:\yash\billsnap\env\lib\site-packages\django\db\backends\utils.py", line 103, in execute
    return super().execute(sql, params)
  File "D:\yash\billsnap\env\lib\site-packages\django\db\backends\utils.py", line 67, in execute
    return self._execute_with_wrappers(
  File "D:\yash\billsnap\env\lib\site-packages\django\db\backends\utils.py", line 80, in _execute_with_wrappers
    return executor(sql, params, many, context)
  File "D:\yash\billsnap\env\lib\site-packages\django\db\backends\utils.py", line 84, in _execute
    with self.db.wrap_database_errors:
  File "D:\yash\billsnap\env\lib\site-packages\django\db\utils.py", line 91, in __exit__
    raise dj_exc_value.with_traceback(traceback) from exc_value
  File "D:\yash\billsnap\env\lib\site-packages\django\db\backends\utils.py", line 89, in _execute
    return self.cursor.execute(sql, params)
  File "D:\yash\billsnap\env\lib\site-packages\django\db\backends\sqlite3\base.py", line 357, in execute
    return Database.Cursor.execute(self, query, params)
django.db.utils.IntegrityError: UNIQUE constraint failed: apps_applists.slug
[2022-12-05T00:23:39] ERROR [django.request.log_response:241] Internal Server Error: /apps/editapp/instagram
Traceback (most recent call last):
  File "D:\yash\billsnap\env\lib\site-packages\django\db\backends\utils.py", line 89, in _execute
    return self.cursor.execute(sql, params)
  File "D:\yash\billsnap\env\lib\site-packages\django\db\backends\sqlite3\base.py", line 357, in execute
    return Database.Cursor.execute(self, query, params)
sqlite3.IntegrityError: UNIQUE constraint failed: apps_applists.slug

The above exception was the direct cause of the following exception:

Traceback (most recent call last):
  File "D:\yash\billsnap\env\lib\site-packages\django\core\handlers\exception.py", line 55, in inner
    response = get_response(request)
  File "D:\yash\billsnap\env\lib\site-packages\django\core\handlers\base.py", line 197, in _get_response
    response = wrapped_callback(request, *callback_args, **callback_kwargs)
  File "D:\yash\billsnap\env\lib\site-packages\django\contrib\auth\decorators.py", line 23, in _wrapped_view
    return view_func(request, *args, **kwargs)
  File "D:\yash\billsnap\billsnapdec\apps\views.py", line 95, in editapp
    app.save()
  File "D:\yash\billsnap\billsnapdec\apps\models.py", line 33, in save
    super(applists, self).save()
  File "D:\yash\billsnap\env\lib\site-packages\django\db\models\base.py", line 812, in save
    self.save_base(
  File "D:\yash\billsnap\env\lib\site-packages\django\db\models\base.py", line 863, in save_base
    updated = self._save_table(
  File "D:\yash\billsnap\env\lib\site-packages\django\db\models\base.py", line 1006, in _save_table
    results = self._do_insert(
  File "D:\yash\billsnap\env\lib\site-packages\django\db\models\base.py", line 1047, in _do_insert
    return manager._insert(
  File "D:\yash\billsnap\env\lib\site-packages\django\db\models\manager.py", line 85, in manager_method
    return getattr(self.get_queryset(), name)(*args, **kwargs)
  File "D:\yash\billsnap\env\lib\site-packages\django\db\models\query.py", line 1790, in _insert
    return query.get_compiler(using=using).execute_sql(returning_fields)
  File "D:\yash\billsnap\env\lib\site-packages\django\db\models\sql\compiler.py", line 1660, in execute_sql
    cursor.execute(sql, params)
  File "D:\yash\billsnap\env\lib\site-packages\django\db\backends\utils.py", line 103, in execute
    return super().execute(sql, params)
  File "D:\yash\billsnap\env\lib\site-packages\django\db\backends\utils.py", line 67, in execute
    return self._execute_with_wrappers(
  File "D:\yash\billsnap\env\lib\site-packages\django\db\backends\utils.py", line 80, in _execute_with_wrappers
    return executor(sql, params, many, context)
  File "D:\yash\billsnap\env\lib\site-packages\django\db\backends\utils.py", line 84, in _execute
    with self.db.wrap_database_errors:
  File "D:\yash\billsnap\env\lib\site-packages\django\db\utils.py", line 91, in __exit__
    raise dj_exc_value.with_traceback(traceback) from exc_value
  File "D:\yash\billsnap\env\lib\site-packages\django\db\backends\utils.py", line 89, in _execute
    return self.cursor.execute(sql, params)
  File "D:\yash\billsnap\env\lib\site-packages\django\db\backends\sqlite3\base.py", line 357, in execute
    return Database.Cursor.execute(self, query, params)
django.db.utils.IntegrityError: UNIQUE constraint failed: apps_applists.slug
[2022-12-05T00:24:04] INFO [root.deleteapp:77] neha_deleted an app
[2022-12-05T00:24:04] INFO [root.showapps:70] neha_seen the whole applist
[2022-12-05T00:24:18] WARNING [django.request.log_response:241] Not Found: /apps/instagram/dashboard/assets/img/ivancik.jpg
[2022-12-05T00:24:32] ERROR [django.request.log_response:241] Internal Server Error: /apps/editapp/instagram
Traceback (most recent call last):
  File "D:\yash\billsnap\env\lib\site-packages\django\db\backends\utils.py", line 89, in _execute
    return self.cursor.execute(sql, params)
  File "D:\yash\billsnap\env\lib\site-packages\django\db\backends\sqlite3\base.py", line 357, in execute
    return Database.Cursor.execute(self, query, params)
sqlite3.IntegrityError: UNIQUE constraint failed: apps_applists.slug

The above exception was the direct cause of the following exception:

Traceback (most recent call last):
  File "D:\yash\billsnap\env\lib\site-packages\django\core\handlers\exception.py", line 55, in inner
    response = get_response(request)
  File "D:\yash\billsnap\env\lib\site-packages\django\core\handlers\base.py", line 197, in _get_response
    response = wrapped_callback(request, *callback_args, **callback_kwargs)
  File "D:\yash\billsnap\env\lib\site-packages\django\contrib\auth\decorators.py", line 23, in _wrapped_view
    return view_func(request, *args, **kwargs)
  File "D:\yash\billsnap\billsnapdec\apps\views.py", line 95, in editapp
    app.save()
  File "D:\yash\billsnap\billsnapdec\apps\models.py", line 33, in save
    super(applists, self).save()
  File "D:\yash\billsnap\env\lib\site-packages\django\db\models\base.py", line 812, in save
    self.save_base(
  File "D:\yash\billsnap\env\lib\site-packages\django\db\models\base.py", line 863, in save_base
    updated = self._save_table(
  File "D:\yash\billsnap\env\lib\site-packages\django\db\models\base.py", line 1006, in _save_table
    results = self._do_insert(
  File "D:\yash\billsnap\env\lib\site-packages\django\db\models\base.py", line 1047, in _do_insert
    return manager._insert(
  File "D:\yash\billsnap\env\lib\site-packages\django\db\models\manager.py", line 85, in manager_method
    return getattr(self.get_queryset(), name)(*args, **kwargs)
  File "D:\yash\billsnap\env\lib\site-packages\django\db\models\query.py", line 1790, in _insert
    return query.get_compiler(using=using).execute_sql(returning_fields)
  File "D:\yash\billsnap\env\lib\site-packages\django\db\models\sql\compiler.py", line 1660, in execute_sql
    cursor.execute(sql, params)
  File "D:\yash\billsnap\env\lib\site-packages\django\db\backends\utils.py", line 103, in execute
    return super().execute(sql, params)
  File "D:\yash\billsnap\env\lib\site-packages\django\db\backends\utils.py", line 67, in execute
    return self._execute_with_wrappers(
  File "D:\yash\billsnap\env\lib\site-packages\django\db\backends\utils.py", line 80, in _execute_with_wrappers
    return executor(sql, params, many, context)
  File "D:\yash\billsnap\env\lib\site-packages\django\db\backends\utils.py", line 84, in _execute
    with self.db.wrap_database_errors:
  File "D:\yash\billsnap\env\lib\site-packages\django\db\utils.py", line 91, in __exit__
    raise dj_exc_value.with_traceback(traceback) from exc_value
  File "D:\yash\billsnap\env\lib\site-packages\django\db\backends\utils.py", line 89, in _execute
    return self.cursor.execute(sql, params)
  File "D:\yash\billsnap\env\lib\site-packages\django\db\backends\sqlite3\base.py", line 357, in execute
    return Database.Cursor.execute(self, query, params)
django.db.utils.IntegrityError: UNIQUE constraint failed: apps_applists.slug
[2022-12-05T00:25:38] INFO [django.utils.autoreload.trigger_reload:266] D:\yash\billsnap\billsnapdec\apps\views.py changed, reloading.
[2022-12-05T00:25:47] INFO [django.utils.autoreload.trigger_reload:266] D:\yash\billsnap\billsnapdec\apps\views.py changed, reloading.
[2022-12-05T00:25:55] INFO [django.utils.autoreload.trigger_reload:266] D:\yash\billsnap\billsnapdec\apps\views.py changed, reloading.
[2022-12-05T00:26:01] INFO [django.utils.autoreload.trigger_reload:266] D:\yash\billsnap\billsnapdec\apps\views.py changed, reloading.
[2022-12-05T00:26:06] INFO [django.utils.autoreload.trigger_reload:266] D:\yash\billsnap\billsnapdec\apps\views.py changed, reloading.
[2022-12-05T00:26:10] INFO [django.utils.autoreload.trigger_reload:266] D:\yash\billsnap\billsnapdec\apps\views.py changed, reloading.
[2022-12-05T00:26:25] INFO [root.editapp:95] neha_edited an app
[2022-12-05T00:32:12] INFO [django.utils.autoreload.trigger_reload:266] D:\yash\billsnap\billsnapdec\dashboard\views.py changed, reloading.
[2022-12-05T00:32:24] INFO [django.utils.autoreload.trigger_reload:266] D:\yash\billsnap\billsnapdec\dashboard\views.py changed, reloading.
[2022-12-05T00:33:52] ERROR [django.request.log_response:241] Internal Server Error: /apps/instagram/appinfo/
Traceback (most recent call last):
  File "D:\yash\billsnap\env\lib\site-packages\django\core\handlers\exception.py", line 55, in inner
    response = get_response(request)
  File "D:\yash\billsnap\env\lib\site-packages\django\core\handlers\base.py", line 197, in _get_response
    response = wrapped_callback(request, *callback_args, **callback_kwargs)
  File "D:\yash\billsnap\env\lib\site-packages\django\contrib\auth\decorators.py", line 23, in _wrapped_view
    return view_func(request, *args, **kwargs)
  File "D:\yash\billsnap\billsnapdec\dashboard\views.py", line 209, in appinfo
    plan = app.plan_set.all().filter(default_for_customer=True)[0]
  File "D:\yash\billsnap\env\lib\site-packages\django\db\models\query.py", line 446, in __getitem__
    return qs._result_cache[0]
IndexError: list index out of range
[2022-12-05T00:34:16] ERROR [django.request.log_response:241] Internal Server Error: /apps/ehee/appinfo/
Traceback (most recent call last):
  File "D:\yash\billsnap\env\lib\site-packages\django\core\handlers\exception.py", line 55, in inner
    response = get_response(request)
  File "D:\yash\billsnap\env\lib\site-packages\django\core\handlers\base.py", line 197, in _get_response
    response = wrapped_callback(request, *callback_args, **callback_kwargs)
  File "D:\yash\billsnap\env\lib\site-packages\django\contrib\auth\decorators.py", line 23, in _wrapped_view
    return view_func(request, *args, **kwargs)
  File "D:\yash\billsnap\billsnapdec\dashboard\views.py", line 208, in appinfo
    app = applists.objects.get(slug=slug)
  File "D:\yash\billsnap\env\lib\site-packages\django\db\models\manager.py", line 85, in manager_method
    return getattr(self.get_queryset(), name)(*args, **kwargs)
  File "D:\yash\billsnap\env\lib\site-packages\django\db\models\query.py", line 650, in get
    raise self.model.DoesNotExist(
apps.models.applists.DoesNotExist: applists matching query does not exist.
[2022-12-05T00:34:20] ERROR [django.request.log_response:241] Internal Server Error: /apps/eheee/appinfo/
Traceback (most recent call last):
  File "D:\yash\billsnap\env\lib\site-packages\django\core\handlers\exception.py", line 55, in inner
    response = get_response(request)
  File "D:\yash\billsnap\env\lib\site-packages\django\core\handlers\base.py", line 197, in _get_response
    response = wrapped_callback(request, *callback_args, **callback_kwargs)
  File "D:\yash\billsnap\env\lib\site-packages\django\contrib\auth\decorators.py", line 23, in _wrapped_view
    return view_func(request, *args, **kwargs)
  File "D:\yash\billsnap\billsnapdec\dashboard\views.py", line 208, in appinfo
    app = applists.objects.get(slug=slug)
  File "D:\yash\billsnap\env\lib\site-packages\django\db\models\manager.py", line 85, in manager_method
    return getattr(self.get_queryset(), name)(*args, **kwargs)
  File "D:\yash\billsnap\env\lib\site-packages\django\db\models\query.py", line 650, in get
    raise self.model.DoesNotExist(
apps.models.applists.DoesNotExist: applists matching query does not exist.
[2022-12-05T00:34:25] INFO [root.showapps:70] neha_seen the whole applist
[2022-12-05T00:34:32] WARNING [django.request.log_response:241] Not Found: /apps/darling/dashboard/assets/img/ivancik.jpg
[2022-12-05T00:39:44] INFO [root.showapps:70] neha_seen the whole applist
[2022-12-05T00:42:09] INFO [root.showapps:70] neha_seen the whole applist
[2022-12-05T00:42:27] WARNING [django.request.log_response:241] Not Found: /apps/darling/dashboard/assets/img/ivancik.jpg
[2022-12-05T00:43:05] WARNING [django.request.log_response:241] Not Found: /apps/darling/dashboard/assets/img/ivancik.jpg
[2022-12-05T00:47:20] WARNING [django.request.log_response:241] Not Found: /favicon.ico
[2022-12-05T00:50:30] WARNING [django.request.log_response:241] Not Found: /favicon.ico
[2022-12-05T00:52:49] WARNING [django.request.log_response:241] Not Found: /apps/darling/dashboard/assets/img/ivancik.jpg
[2022-12-05T01:00:22] INFO [django.utils.autoreload.trigger_reload:266] D:\yash\billsnap\billsnapdec\groups\views.py changed, reloading.
